Workbook
Name country_codes: Table10[#All]
Name list_manufacturer: #REF!
Name list_producer: #REF!
Name min_industry_list: Table3[#All]
Name min_matrix: Table112[#All]
Name min_sector_list: Table3[#All]
Name ref_data: Table112[]
Name sector_code: Table8[#All]

Sheet 00_README
A1: Purpose | B1: This workbook explores the relationship between strategic minerals, industrial sectors, manufacturing economies and national development strategies. The objective is not to estimate market value but to understand how different countries view strategic resources and how those resources support industrial capability.
A3: Structure | B3: Crit_Min_Frameworks - Compares national mineral strategies 01_raw_data - Source geological data 02_ref_data - Country-mineral matrix 03_global_tot - Producer counts 03_calc_demand - Scarcity / importance calculations 03_calc_weight - Country scores Mineral Industry List - Mineral Product Sector mapping sector-mineral matrix - Demand analysis sector-country matrix - Manufacturing geography sector-country list - Source company dataset Country Code - ISO3 reference Mineral Codes - Mineral reference Sector Codes - Sector definitions and elasticity
A5: Key Assumptions | B5: Geographic Deposit occurrence is used instead of production volume. Industrial Major firms are proxies for global industrial activity Classification Product-to-sector mapping used with engineering judgment Strategic Frameworks Critical mineral lists are treated as expressions of national priorities rather than objective truth.
A7: Limitations | B7: No mid-stream data from extraction to final manufactured products No trade flow data No production share data No demographic data No value capture data

Sheet Crit_Min_Frameworks
A1: Mineral | B1: Recognition_Score | C1: USGS | D1: EU | E1: AUS | F1: UK_Critical | G1: UK_Growth | H1: MYS | I1: ZWE | J1: CHN_strategic | K1: ZAF | L1: IND
A2: ALU | B2: =SUM(Table9[[#This Row],[USGS]]:Table9[[#This Row],[IND]]) -> 8 | C2: 1 | D2: 1 | E2: 1 | F2: 1 | G2: 1 | H2: 1 | I2: 0 | J2: 1 | K2: 1 | L2: 0
A3: ANT | B3: =SUM(Table9[[#This Row],[USGS]]:Table9[[#This Row],[IND]]) -> 8 | C3: 1 | D3: 1 | E3: 1 | F3: 1 | G3: 1 | H3: 0 | I3: 1 | J3: 1 | K3: 0 | L3: 1
A4: ARS | B4: =SUM(Table9[[#This Row],[USGS]]:Table9[[#This Row],[IND]]) -> 3 | C4: 1 | D4: 1 | E4: 1 | F4: 0 | G4: 0 | H4: 0 | I4: 0 | J4: 0 | K4: 0 | L4: 0
A5: BAR | B5: =SUM(Table9[[#This Row],[USGS]]:Table9[[#This Row],[IND]]) -> 2 | C5: 1 | D5: 1 | E5: 0 | F5: 0 | G5: 0 | H5: 0 | I5: 0 | J5: 0 | K5: 0 | L5: 0
A6: BER | B6: =SUM(Table9[[#This Row],[USGS]]:Table9[[#This Row],[IND]]) -> 5 | C6: 1 | D6: 1 | E6: 1 | F6: 0 | G6: 1 | H6: 0 | I6: 0 | J6: 0 | K6: 0 | L6: 1
A7: BIS | B7: =SUM(Table9[[#This Row],[USGS]]:Table9[[#This Row],[IND]]) -> 5 | C7: 1 | D7: 1 | E7: 1 | F7: 1 | G7: 0 | H7: 0 | I7: 0 | J7: 0 | K7: 0 | L7: 1
A8: BOR | B8: =SUM(Table9[[#This Row],[USGS]]:Table9[[#This Row],[IND]]) -> 3 | C8: 1 | D8: 1 | E8: 0 | F8: 1 | G8: 0 | H8: 0 | I8: 0 | J8: 0 | K8: 0 | L8: 0
A9: CES | B9: =SUM(Table9[[#This Row],[USGS]]:Table9[[#This Row],[IND]]) -> 2 | C9: 1 | D9: 0 | E9: 0 | F9: 0 | G9: 0 | H9: 0 | I9: 0 | J9: 1 | K9: 0 | L9: 0
A10: CHR | B10: =SUM(Table9[[#This Row],[USGS]]:Table9[[#This Row],[IND]]) -> 6 | C10: 1 | D10: 0 | E10: 1 | F10: 0 | G10: 1 | H10: 0 | I10: 1 | J10: 1 | K10: 1 | L10: 0
A11: COB | B11: =SUM(Table9[[#This Row],[USGS]]:Table9[[#This Row],[IND]]) -> 9 | C11: 1 | D11: 1 | E11: 1 | F11: 1 | G11: 1 | H11: 0 | I11: 1 | J11: 1 | K11: 1 | L11: 1
A12: COP | B12: =SUM(Table9[[#This Row],[USGS]]:Table9[[#This Row],[IND]]) -> 7 | C12: 1 | D12: 1 | E12: 0 | F12: 0 | G12: 1 | H12: 0 | I12: 1 | J12: 1 | K12: 1 | L12: 1
A13: FLU | B13: =SUM(Table9[[#This Row],[USGS]]:Table9[[#This Row],[IND]]) -> 4 | C13: 1 | D13: 1 | E13: 0 | F13: 0 | G13: 0 | H13: 0 | I13: 0 | J13: 1 | K13: 1 | L13: 0
... A58: CAD | B58: =SUM(Table9[[#This Row],[USGS]]:Table9[[#This Row],[IND]]) -> 1 | C58: 0 | D58: 0 | E58: 0 | F58: 0 | G58: 0 | H58: 0 | I58: 0 | J58: 0 | K58: 0 | L58: 1

Sheet 01_raw_data
A1: Mineral | B1: Countries with Significant Deposits
A2: Aluminum (Bauxite) | B2: Guinea, Australia, Brazil, Vietnam, India, Jamaica
A3: Antimony | B3: China, Russia, Tajikistan, Myanmar, Bolivia, Turkiye
A4: Arsenic | B4: China, Peru, Morocco, Russia, Mexico
A5: Barite | B5: China, India, Morocco, Kazakhstan, United States
A6: Beryllium | B6: United States, China, Brazil, Madagascar, Mozambique
A7: Bismuth | B7: China, Mexico, Peru, Bolivia, Vietnam
A8: Boron | B8: Turkiye, United States, Argentina, Chile, Russia
A9: Cesium | B9: Canada, Zimbabwe, Australia, Namibia
A10: Chromium | B10: South Africa, Kazakhstan, India, Turkiye, Finland
A11: Cobalt | B11: DRC, Australia, Indonesia, Cuba, Canada
A12: Copper | B12: Chile, Peru, Australia, DRC, Russia, United States, Zambia
... A47: REE | B47: China, Brazil, Vietnam, Australia, Russia, India, United States,Greenland, Canada, South Africa, Tanzania, Madagascar, Malawi

Sheet 02_ref_data
A1: Country Code | B1: Continent | C1: ALU | D1: ANT | E1: ARS | F1: BAR | G1: BER | H1: BIS | I1: BOR | J1: CES | K1: CHR | L1: COB | M1: COP | N1: FLU | O1: GAL | P1: GER | Q1: GRA | R1: HAF | S1: IND | T1: IRI | U1: LED | V1: LIT | W1: MAG | X1: MAN | Y1: MCO | Z1: NIC | AA1: NIO | AB1: PAL | AC1: PHO | AD1: PLA | AE1: POT | AF1: RHE | AG1: RHO | AH1: RUB | AI1: RUT | AJ1: SCA | AK1: SIL | AL1: SLV | AM1: TAN | AN1: TEL | AO1: TIN | AP1: TIT | AQ1: TUN | AR1: URA | AS1: VAN | AT1: ZIN | AU1: ZIR | AV1: REE | AW1: Total Minerals
A2: CHN | B2: =VLOOKUP(Table112[[#This Row],[Country Code]],Table10[[ISO3]:[Continent]],2,FALSE) -> Asia | C2: 0 | D2: 1 | E2: 1 | F2: 1 | G2: 1 | H2: 1 | I2: 0 | J2: 0 | K2: 0 | L2: 0 | M2: 0 | N2: 1 | O2: 1 | P2: 1 | Q2: 1 | R2: 0 | S2: 1 | T2: 0 | U2: 1 | V2: 1 | W2: 1 | X2: 0 | Y2: 0 | Z2: 0 | AA2: 0 | AB2: 0 | AC2: 1 | AD2: 0 | AE2: 1 | AF2: 0 | AG2: 0 | AH2: 0 | AI2: 0 | AJ2: 1 | AK2: 1 | AL2: 1 | AM2: 0 | AN2: 1 | AO2: 1 | AP2: 1 | AQ2: 1 | AR2: 0 | AS2: 1 | AT2: 1 | AU2: 0 | AV2: 1 | AW2: =SUM(Table112[[#This Row],[ALU]]:Table112[[#This Row],[REE]]) -> 25
A3: AUS | B3: =VLOOKUP(Table112[[#This Row],[Country Code]],Table10[[ISO3]:[Continent]],2,FALSE) -> Oceania | C3: 1 | D3: 0 | E3: 0 | F3: 0 | G3: 0 | H3: 0 | I3: 0 | J3: 1 | K3: 0 | L3: 1 | M3: 1 | N3: 0 | O3: 1 | P3: 0 | Q3: 0 | R3: 1 | S3: 1 | T3: 0 | U3: 1 | V3: 1 | W3: 0 | X3: 1 | Y3: 1 | Z3: 1 | AA3: 1 | AB3: 0 | AC3: 0 | AD3: 0 | AE3: 0 | AF3: 0 | AG3: 0 | AH3: 1 | AI3: 0 | AJ3: 1 | AK3: 1 | AL3: 1 | AM3: 1 | AN3: 0 | AO3: 0 | AP3: 1 | AQ3: 0 | AR3: 1 | AS3: 1 | AT3: 1 | AU3: 1 | AV3: 1 | AW3: =SUM(Table112[[#This Row],[ALU]]:Table112[[#This Row],[REE]]) -> 24
A4: RUS | B4: =VLOOKUP(Table112[[#This Row],[Country Code]],Table10[[ISO3]:[Continent]],2,FALSE) -> Eurasia | C4: 0 | D4: 1 | E4: 1 | F4: 0 | G4: 0 | H4: 0 | I4: 1 | J4: 0 | K4: 0 | L4: 0 | M4: 1 | N4: 0 | O4: 0 | P4: 1 | Q4: 0 | R4: 0 | S4: 0 | T4: 1 | U4: 0 | V4: 0 | W4: 1 | X4: 0 | Y4: 1 | Z4: 1 | AA4: 0 | AB4: 1 | AC4: 0 | AD4: 1 | AE4: 1 | AF4: 0 | AG4: 1 | AH4: 0 | AI4: 1 | AJ4: 1 | AK4: 0 | AL4: 0 | AM4: 0 | AN4: 0 | AO4: 0 | AP4: 0 | AQ4: 1 | AR4: 0 | AS4: 1 | AT4: 0 | AU4: 0 | AV4: 1 | AW4: =SUM(Table112[[#This Row],[ALU]]:Table112[[#This Row],[REE]]) -> 18
A5: CAN | B5: =VLOOKUP(Table112[[#This Row],[Country Code]],Table10[[ISO3]:[Continent]],2,FALSE) -> North America | C5: 0 | D5: 0 | E5: 0 | F5: 0 | G5: 0 | H5: 0 | I5: 0 | J5: 1 | K5: 0 | L5: 1 | M5: 0 | N5: 0 | O5: 0 | P5: 1 | Q5: 0 | R5: 0 | S5: 1 | T5: 1 | U5: 0 | V5: 1 | W5: 0 | X5: 0 | Y5: 1 | Z5: 1 | AA5: 1 | AB5: 1 | AC5: 0 | AD5: 1 | AE5: 1 | AF5: 0 | AG5: 0 | AH5: 1 | AI5: 0 | AJ5: 0 | AK5: 0 | AL5: 0 | AM5: 0 | AN5: 1 | AO5: 0 | AP5: 0 | AQ5: 0 | AR5: 1 | AS5: 0 | AT5: 0 | AU5: 0 | AV5: 1 | AW5: =SUM(Table112[[#This Row],[ALU]]:Table112[[#This Row],[REE]]) -> 16
A6: ZAF | B6: =VLOOKUP(Table112[[#This Row],[Country Code]],Table10[[ISO3]:[Continent]],2,FALSE) -> Africa | C6: 0 | D6: 0 | E6: 0 | F6: 0 | G6: 0 | H6: 0 | I6: 0 | J6: 0 | K6: 1 | L6: 0 | M6: 0 | N6: 1 | O6: 0 | P6: 0 | Q6: 0 | R6: 1 | S6: 0 | T6: 1 | U6: 0 | V6: 0 | W6: 0 | X6: 1 | Y6: 0 | Z6: 0 | AA6: 0 | AB6: 1 | AC6: 0 | AD6: 1 | AE6: 0 | AF6: 0 | AG6: 1 | AH6: 0 | AI6: 1 | AJ6: 0 | AK6: 0 | AL6: 0 | AM6: 0 | AN6: 0 | AO6: 0 | AP6: 1 | AQ6: 0 | AR6: 0 | AS6: 1 | AT6: 0 | AU6: 1 | AV6: 1 | AW6: =SUM(Table112[[#This Row],[ALU]]:Table112[[#This Row],[REE]]) -> 13
A7: USA | B7: =VLOOKUP(Table112[[#This Row],[Country Code]],Table10[[ISO3]:[Continent]],2,FALSE) -> North America | C7: 0 | D7: 0 | E7: 0 | F7: 1 | G7: 1 | H7: 0 | I7: 1 | J7: 0 | K7: 0 | L7: 0 | M7: 1 | N7: 0 | O7: 0 | P7: 1 | Q7: 0 | R7: 1 | S7: 0 | T7: 0 | U7: 1 | V7: 0 | W7: 0 | X7: 0 | Y7: 1 | Z7: 0 | AA7: 0 | AB7: 1 | AC7: 0 | AD7: 0 | AE7: 0 | AF7: 1 | AG7: 0 | AH7: 0 | AI7: 0 | AJ7: 0 | AK7: 1 | AL7: 0 | AM7: 0 | AN7: 0 | AO7: 0 | AP7: 0 | AQ7: 0 | AR7: 0 | AS7: 0 | AT7: 0 | AU7: 1 | AV7: 1 | AW7: =SUM(Table112[[#This Row],[ALU]]:Table112[[#This Row],[REE]]) -> 13
A8: BRA | B8: =VLOOKUP(Table112[[#This Row],[Country Code]],Table10[[ISO3]:[Continent]],2,FALSE) -> South America | C8: 1 | D8: 0 | E8: 0 | F8: 0 | G8: 1 | H8: 0 | I8: 0 | J8: 0 | K8: 0 | L8: 0 | M8: 0 | N8: 0 | O8: 0 | P8: 0 | Q8: 1 | R8: 0 | S8: 0 | T8: 0 | U8: 0 | V8: 0 | W8: 1 | X8: 1 | Y8: 0 | Z8: 1 | AA8: 1 | AB8: 0 | AC8: 0 | AD8: 0 | AE8: 0 | AF8: 0 | AG8: 0 | AH8: 0 | AI8: 0 | AJ8: 0 | AK8: 1 | AL8: 0 | AM8: 1 | AN8: 0 | AO8: 0 | AP8: 0 | AQ8: 0 | AR8: 0 | AS8: 1 | AT8: 0 | AU8: 0 | AV8: 1 | AW8: =SUM(Table112[[#This Row],[ALU]]:Table112[[#This Row],[REE]]) -> 11
A9: PER | B9: =VLOOKUP(Table112[[#This Row],[Country Code]],Table10[[ISO3]:[Continent]],2,FALSE) -> South America | C9: 0 | D9: 0 | E9: 1 | F9: 0 | G9: 0 | H9: 1 | I9: 0 | J9: 0 | K9: 0 | L9: 0 | M9: 1 | N9: 0 | O9: 0 | P9: 0 | Q9: 0 | R9: 0 | S9: 1 | T9: 0 | U9: 1 | V9: 0 | W9: 0 | X9: 0 | Y9: 0 | Z9: 0 | AA9: 0 | AB9: 0 | AC9: 0 | AD9: 0 | AE9: 0 | AF9: 1 | AG9: 0 | AH9: 0 | AI9: 0 | AJ9: 0 | AK9: 0 | AL9: 1 | AM9: 0 | AN9: 1 | AO9: 1 | AP9: 0 | AQ9: 0 | AR9: 0 | AS9: 0 | AT9: 1 | AU9: 0 | AV9: 0 | AW9: =SUM(Table112[[#This Row],[ALU]]:Table112[[#This Row],[REE]]) -> 10
A10: IND | B10: =VLOOKUP(Table112[[#This Row],[Country Code]],Table10[[ISO3]:[Continent]],2,FALSE) -> Asia | C10: 1 | D10: 0 | E10: 0 | F10: 1 | G10: 0 | H10: 0 | I10: 0 | J10: 0 | K10: 1 | L10: 0 | M10: 0 | N10: 0 | O10: 0 | P10: 0 | Q10: 1 | R10: 1 | S10: 0 | T10: 0 | U10: 0 | V10: 0 | W10: 0 | X10: 0 | Y10: 0 | Z10: 0 | AA10: 0 | AB10: 0 | AC10: 0 | AD10: 0 | AE10: 0 | AF10: 0 | AG10: 0 | AH10: 0 | AI10: 0 | AJ10: 0 | AK10: 0 | AL10: 0 | AM10: 0 | AN10: 0 | AO10: 0 | AP10: 1 | AQ10: 0 | AR10: 0 | AS10: 0 | AT10: 1 | AU10: 1 | AV10: 1 | AW10: =SUM(Table112[[#This Row],[ALU]]:Table112[[#This Row],[REE]]) -> 9
A11: BOL | B11: =VLOOKUP(Table112[[#This Row],[Country Code]],Table10[[ISO3]:[Continent]],2,FALSE) -> South America | C11: 0 | D11: 1 | E11: 0 | F11: 0 | G11: 0 | H11: 1 | I11: 0 | J11: 0 | K11: 0 | L11: 0 | M11: 0 | N11: 0 | O11: 0 | P11: 0 | Q11: 0 | R11: 0 | S11: 1 | T11: 0 | U11: 0 | V11: 1 | W11: 0 | X11: 0 | Y11: 0 | Z11: 0 | AA11: 0 | AB11: 0 | AC11: 0 | AD11: 0 | AE11: 0 | AF11: 0 | AG11: 0 | AH11: 0 | AI11: 0 | AJ11: 0 | AK11: 0 | AL11: 0 | AM11: 0 | AN11: 0 | AO11: 1 | AP11: 0 | AQ11: 1 | AR11: 0 | AS11: 0 | AT11: 0 | AU11: 0 | AV11: 0 | AW11: =SUM(Table112[[#This Row],[ALU]]:Table112[[#This Row],[REE]]) -> 6
A12: MEX | B12: =VLOOKUP(Table112[[#This Row],[Country Code]],Table10[[ISO3]:[Continent]],2,FALSE) -> North America | C12: 0 | D12: 0 | E12: 1 | F12: 0 | G12: 0 | H12: 1 | I12: 0 | J12: 0 | K12: 0 | L12: 0 | M12: 0 | N12: 1 | O12: 0 | P12: 0 | Q12: 0 | R12: 0 | S12: 0 | T12: 0 | U12: 1 | V12: 0 | W12: 0 | X12: 0 | Y12: 0 | Z12: 0 | AA12: 0 | AB12: 0 | AC12: 0 | AD12: 0 | AE12: 0 | AF12: 0 | AG12: 0 | AH12: 0 | AI12: 0 | AJ12: 0 | AK12: 0 | AL12: 1 | AM12: 0 | AN12: 0 | AO12: 0 | AP12: 0 | AQ12: 0 | AR12: 0 | AS12: 0 | AT12: 1 | AU12: 0 | AV12: 0 | AW12: =SUM(Table112[[#This Row],[ALU]]:Table112[[#This Row],[REE]]) -> 6
A13: ZWE | B13: =VLOOKUP(Table112[[#This Row],[Country Code]],Table10[[ISO3]:[Continent]],2,FALSE) -> Africa | C13: 0 | D13: 0 | E13: 0 | F13: 0 | G13: 0 | H13: 0 | I13: 0 | J13: 1 | K13: 0 | L13: 0 | M13: 0 | N13: 0 | O13: 0 | P13: 0 | Q13: 0 | R13: 0 | S13: 0 | T13: 1 | U13: 0 | V13: 0 | W13: 0 | X13: 0 | Y13: 0 | Z13: 0 | AA13: 0 | AB13: 0 | AC13: 0 | AD13: 1 | AE13: 0 | AF13: 0 | AG13: 1 | AH13: 1 | AI13: 1 | AJ13: 0 | AK13: 0 | AL13: 0 | AM13: 0 | AN13: 0 | AO13: 0 | AP13: 0 | AQ13: 0 | AR13: 0 | AS13: 0 | AT13: 0 | AU13: 0 | AV13: 0 | AW13: =SUM(Table112[[#This Row],[ALU]]:Table112[[#This Row],[REE]]) -> 6
... A54: ZMB | B54: =VLOOKUP(Table112[[#This Row],[Country Code]],Table10[[ISO3]:[Continent]],2,FALSE) -> Africa | C54: 0 | D54: 0 | E54: 0 | F54: 0 | G54: 0 | H54: 0 | I54: 0 | J54: 0 | K54: 0 | L54: 0 | M54: 1 | N54: 0 | O54: 0 | P54: 0 | Q54: 0 | R54: 0 | S54: 0 | T54: 0 | U54: 0 | V54: 0 | W54: 0 | X54: 0 | Y54: 0 | Z54: 0 | AA54: 0 | AB54: 0 | AC54: 0 | AD54: 0 | AE54: 0 | AF54: 0 | AG54: 0 | AH54: 0 | AI54: 0 | AJ54: 0 | AK54: 0 | AL54: 0 | AM54: 0 | AN54: 0 | AO54: 0 | AP54: 0 | AQ54: 0 | AR54: 0 | AS54: 0 | AT54: 0 | AU54: 0 | AV54: 0 | AW54: =SUM(Table112[[#This Row],[ALU]]:Table112[[#This Row],[REE]]) -> 1

Sheet 03_global_tot
A1: Mineral Code | B1: Producer Total
A2: REE | B2: =SUM(Table112[REE]) -> 13
A3: COP | B3: =SUM(Table112[COP]) -> 7
A4: ALU | B4: =SUM(Table112[ALU]) -> 6
A5: ANT | B5: =SUM(Table112[ANT]) -> 6
A6: GRA | B6: =SUM(Table112[GRA]) -> 6
A7: LIT | B7: =SUM(Table112[LIT]) -> 6
A8: NIC | B8: =SUM(Table112[NIC]) -> 6
A9: SLV | B9: =SUM(Table112[SLV]) -> 6
A10: TIN | B10: =SUM(Table112[TIN]) -> 6
A11: URA | B11: =SUM(Table112[URA]) -> 6
A12: ARS | B12: =SUM(Table112[ARS]) -> 5
A13: BAR | B13: =SUM(Table112[BAR]) -> 5
A14: BER | B14: =SUM(Table112[BER]) -> 5
A15: BIS | B15: =SUM(Table112[BIS]) -> 5
A16: BOR | B16: =SUM(Table112[BOR]) -> 5
A17: CHR | B17: =SUM(Table112[CHR]) -> 5
A18: COB | B18: =SUM(Table112[COB]) -> 5
A19: FLU | B19: =SUM(Table112[FLU]) -> 5
A20: GAL | B20: =SUM(Table112[GAL]) -> 5
A21: GER | B21: =SUM(Table112[GER]) -> 5
A22: HAF | B22: =SUM(Table112[HAF]) -> 5
A23: IND | B23: =SUM(Table112[IND]) -> 5
A24: LED | B24: =SUM(Table112[LED]) -> 5
A25: MAG | B25: =SUM(Table112[MAG]) -> 5
A26: MAN | B26: =SUM(Table112[MAN]) -> 5
A27: MCO | B27: =SUM(Table112[MCO]) -> 5
A28: PHO | B28: =SUM(Table112[PHO]) -> 5
A29: POT | B29: =SUM(Table112[POT]) -> 5
A30: RHE | B30: =SUM(Table112[RHE]) -> 5
A31: SCA | B31: =SUM(Table112[SCA]) -> 5
A32: SIL | B32: =SUM(Table112[SIL]) -> 5
A33: TAN | B33: =SUM(Table112[TAN]) -> 5
A34: TEL | B34: =SUM(Table112[TEL]) -> 5
A35: TIT | B35: =SUM(Table112[TIT]) -> 5
A36: TUN | B36: =SUM(Table112[TUN]) -> 5
A37: VAN | B37: =SUM(Table112[VAN]) -> 5
A38: ZIN | B38: =SUM(Table112[ZIN]) -> 5
A39: ZIR | B39: =SUM(Table112[ZIR]) -> 5
A40: CES | B40: =SUM(Table112[CES]) -> 4
...

Sheet Mineral Criticality Model
A1: Mineral Code | B1: Producer Country Count | C1: Total Manufacturing Demand | D1: Criticality
A2: NIO | B2: =VLOOKUP(Table2[[#This Row],[Mineral Code]],'03_global_tot'!A$2:B$47,2,FALSE) -> 3 | C2: {=COUNTIF(min_sector_list,Table2[[#This Row],[Mineral Code]])} -> 4 | D2: =Table2[[#This Row],[Total Manufacturing Demand]]/Table2[[#This Row],[Producer Country Count]] -> 1.3333333
A3: RHO | B3: =VLOOKUP(Table2[[#This Row],[Mineral Code]],'03_global_tot'!A$2:B$47,2,FALSE) -> 3 | C3: {=COUNTIF(min_sector_list,Table2[[#This Row],[Mineral Code]])} -> 4 | D3: =Table2[[#This Row],[Total Manufacturing Demand]]/Table2[[#This Row],[Producer Country Count]] -> 1.3333333
A4: RUT | B4: =VLOOKUP(Table2[[#This Row],[Mineral Code]],'03_global_tot'!A$2:B$47,2,FALSE) -> 3 | C4: {=COUNTIF(min_sector_list,Table2[[#This Row],[Mineral Code]])} -> 4 | D4: =Table2[[#This Row],[Total Manufacturing Demand]]/Table2[[#This Row],[Producer Country Count]] -> 1.3333333
A5: CES | B5: =VLOOKUP(Table2[[#This Row],[Mineral Code]],'03_global_tot'!A$2:B$47,2,FALSE) -> 4 | C5: {=COUNTIF(min_sector_list,Table2[[#This Row],[Mineral Code]])} -> 4 | D5: =Table2[[#This Row],[Total Manufacturing Demand]]/Table2[[#This Row],[Producer Country Count]] -> 1
A6: IRI | B6: =VLOOKUP(Table2[[#This Row],[Mineral Code]],'03_global_tot'!A$2:B$47,2,FALSE) -> 4 | C6: {=COUNTIF(min_sector_list,Table2[[#This Row],[Mineral Code]])} -> 4 | D6: =Table2[[#This Row],[Total Manufacturing Demand]]/Table2[[#This Row],[Producer Country Count]] -> 1
A7: PAL | B7: =VLOOKUP(Table2[[#This Row],[Mineral Code]],'03_global_tot'!A$2:B$47,2,FALSE) -> 4 | C7: {=COUNTIF(min_sector_list,Table2[[#This Row],[Mineral Code]])} -> 4 | D7: =Table2[[#This Row],[Total Manufacturing Demand]]/Table2[[#This Row],[Producer Country Count]] -> 1
A8: PLA | B8: =VLOOKUP(Table2[[#This Row],[Mineral Code]],'03_global_tot'!A$2:B$47,2,FALSE) -> 4 | C8: {=COUNTIF(min_sector_list,Table2[[#This Row],[Mineral Code]])} -> 4 | D8: =Table2[[#This Row],[Total Manufacturing Demand]]/Table2[[#This Row],[Producer Country Count]] -> 1
A9: RUB | B9: =VLOOKUP(Table2[[#This Row],[Mineral Code]],'03_global_tot'!A$2:B$47,2,FALSE) -> 4 | C9: {=COUNTIF(min_sector_list,Table2[[#This Row],[Mineral Code]])} -> 4 | D9: =Table2[[#This Row],[Total Manufacturing Demand]]/Table2[[#This Row],[Producer Country Count]] -> 1
A10: ARS | B10: =VLOOKUP(Table2[[#This Row],[Mineral Code]],'03_global_tot'!A$2:B$47,2,FALSE) -> 5 | C10: {=COUNTIF(min_sector_list,Table2[[#This Row],[Mineral Code]])} -> 4 | D10: =Table2[[#This Row],[Total Manufacturing Demand]]/Table2[[#This Row],[Producer Country Count]] -> 0.8
A11: BAR | B11: =VLOOKUP(Table2[[#This Row],[Mineral Code]],'03_global_tot'!A$2:B$47,2,FALSE) -> 5 | C11: {=COUNTIF(min_sector_list,Table2[[#This Row],[Mineral Code]])} -> 4 | D11: =Table2[[#This Row],[Total Manufacturing Demand]]/Table2[[#This Row],[Producer Country Count]] -> 0.8
A12: BER | B12: =VLOOKUP(Table2[[#This Row],[Mineral Code]],'03_global_tot'!A$2:B$47,2,FALSE) -> 5 | C12: {=COUNTIF(min_sector_list,Table2[[#This Row],[Mineral Code]])} -> 4 | D12: =Table2[[#This Row],[Total Manufacturing Demand]]/Table2[[#This Row],[Producer Country Count]] -> 0.8
A13: BIS | B13: =VLOOKUP(Table2[[#This Row],[Mineral Code]],'03_global_tot'!A$2:B$47,2,FALSE) -> 5 | C13: {=COUNTIF(min_sector_list,Table2[[#This Row],[Mineral Code]])} -> 4 | D13: =Table2[[#This Row],[Total Manufacturing Demand]]/Table2[[#This Row],[Producer Country Count]] -> 0.8
... A47: REE | B47: =VLOOKUP(Table2[[#This Row],[Mineral Code]],'03_global_tot'!A$2:B$47,2,FALSE) -> 13 | C47: {=COUNTIF(min_sector_list,Table2[[#This Row],[Mineral Code]])} -> 4 | D47: =Table2[[#This Row],[Total Manufacturing Demand]]/Table2[[#This Row],[Producer Country Count]] -> 0.30769231

Sheet Country Strategic Scores
A1: Country Code | B1: ALU | C1: ANT | D1: ARS | E1: BAR | F1: BER | G1: BIS | H1: BOR | I1: CES | J1: CHR | K1: COB | L1: COP | M1: FLU | N1: GAL | O1: GER | P1: GRA | Q1: HAF | R1: IND | S1: IRI | T1: LED | U1: LIT | V1: MAG | W1: MAN | X1: MCO | Y1: NIC | Z1: NIO | AA1: PAL | AB1: PHO | AC1: PLA | AD1: POT | AE1: RHE | AF1: RHO | AG1: RUB | AH1: RUT | AI1: SCA | AJ1: SIL | AK1: SLV | AL1: TAN | AM1: TEL | AN1: TIN | AO1: TIT | AP1: TUN | AQ1: URA | AR1: VAN | AS1: ZIN | AT1: ZIR | AU1: REE | AV1: Strategic Mineral Score
A2: CHN | B2: =VLOOKUP(Table15[[#Headers],[ALU]],Table2[#All],4,FALSE)*Table112[[#This Row],[ALU]] -> 0 | C2: =VLOOKUP(Table15[[#Headers],[ANT]],Table2[#All],4,FALSE)*Table112[[#This Row],[ANT]] -> 0.66666667 | D2: =VLOOKUP(Table15[[#Headers],[ARS]],Table2[#All],4,FALSE) -> 0.8 | E2: =VLOOKUP(Table15[[#Headers],[BAR]],Table2[#All],4,FALSE)*Table112[[#This Row],[BAR]] -> 0.8 | F2: =VLOOKUP(Table15[[#Headers],[BER]],Table2[#All],4,FALSE)*Table112[[#This Row],[BER]] -> 0.8 | G2: =VLOOKUP(Table15[[#Headers],[BIS]],Table2[#All],4,FALSE)*Table112[[#This Row],[BIS]] -> 0.8 | H2: =VLOOKUP(Table15[[#Headers],[BOR]],Table2[#All],4,FALSE)*Table112[[#This Row],[BOR]] -> 0 | I2: =VLOOKUP(Table15[[#Headers],[CES]],Table2[#All],4,FALSE)*Table112[[#This Row],[CES]] -> 0 | J2: =VLOOKUP(Table15[[#Headers],[CHR]],Table2[#All],4,FALSE)*Table112[[#This Row],[CHR]] -> 0 | K2: =VLOOKUP(Table15[[#Headers],[COB]],Table2[#All],4,FALSE)*Table112[[#This Row],[COB]] -> 0 | L2: =VLOOKUP(Table15[[#Headers],[COP]],Table2[#All],4,FALSE)*Table112[[#This Row],[COP]] -> 0 | M2: =VLOOKUP(Table15[[#Headers],[FLU]],Table2[#All],4,FALSE)*Table112[[#This Row],[FLU]] -> 0.8 | N2: =VLOOKUP(Table15[[#Headers],[GAL]],Table2[#All],4,FALSE)*Table112[[#This Row],[GAL]] -> 0.8 | O2: =VLOOKUP(Table15[[#Headers],[GER]],Table2[#All],4,FALSE)*Table112[[#This Row],[GER]] -> 0.8 | P2: =VLOOKUP(Table15[[#Headers],[GRA]],Table2[#All],4,FALSE)*Table112[[#This Row],[GRA]] -> 0.66666667 | Q2: =VLOOKUP(Table15[[#Headers],[HAF]],Table2[#All],4,FALSE)*Table112[[#This Row],[HAF]] -> 0 | R2: =VLOOKUP(Table15[[#Headers],[IND]],Table2[#All],4,FALSE)*Table112[[#This Row],[IND]] -> 0.8 | S2: =VLOOKUP(Table15[[#Headers],[IRI]],Table2[#All],4,FALSE)*Table112[[#This Row],[IRI]] -> 0 | T2: =VLOOKUP(Table15[[#Headers],[LED]],Table2[#All],4,FALSE)*Table112[[#This Row],[LED]] -> 0.8 | U2: =VLOOKUP(Table15[[#Headers],[LIT]],Table2[#All],4,FALSE)*Table112[[#This Row],[LIT]] -> 0.66666667 | V2: =VLOOKUP(Table15[[#Headers],[MAG]],Table2[#All],4,FALSE)*Table112[[#This Row],[MAG]] -> 0.8 | W2: =VLOOKUP(Table15[[#Headers],[MAN]],Table2[#All],4,FALSE)*Table112[[#This Row],[MAN]] -> 0 | X2: =VLOOKUP(Table15[[#Headers],[MCO]],Table2[#All],4,FALSE)*Table112[[#This Row],[MCO]] -> 0 | Y2: =VLOOKUP(Table15[[#Headers],[NIC]],Table2[#All],4,FALSE)*Table112[[#This Row],[NIC]] -> 0 | Z2: =VLOOKUP(Table15[[#Headers],[NIO]],Table2[#All],4,FALSE)*Table112[[#This Row],[NIO]] -> 0 | AA2: =VLOOKUP(Table15[[#Headers],[PAL]],Table2[#All],4,FALSE)*Table112[[#This Row],[PAL]] -> 0 | AB2: =VLOOKUP(Table15[[#Headers],[PHO]],Table2[#All],4,FALSE)*Table112[[#This Row],[PHO]] -> 0.8 | AC2: =VLOOKUP(Table15[[#Headers],[PLA]],Table2[#All],4,FALSE)*Table112[[#This Row],[PLA]] -> 0 | AD2: =VLOOKUP(Table15[[#Headers],[POT]],Table2[#All],4,FALSE)*Table112[[#This Row],[POT]] -> 0.6 | AE2: =VLOOKUP(Table15[[#Headers],[RHE]],Table2[#All],4,FALSE)*Table112[[#This Row],[RHE]] -> 0 | AF2: =VLOOKUP(Table15[[#Headers],[RHO]],Table2[#All],4,FALSE)*Table112[[#This Row],[RHO]] -> 0 | AG2: =VLOOKUP(Table15[[#Headers],[RUB]],Table2[#All],4,FALSE)*Table112[[#This Row],[RUB]] -> 0 | AH2: =VLOOKUP(Table15[[#Headers],[RUT]],Table2[#All],4,FALSE)*Table112[[#This Row],[RUT]] -> 0 | AI2: =VLOOKUP(Table15[[#Headers],[SCA]],Table2[#All],4,FALSE)*Table112[[#This Row],[SCA]] -> 0.6 | AJ2: =VLOOKUP(Table15[[#Headers],[SIL]],Table2[#All],4,FALSE)*Table112[[#This Row],[SIL]] -> 0.8 | AK2: =VLOOKUP(Table15[[#Headers],[SLV]],Table2[#All],4,FALSE)*Table112[[#This Row],[SLV]] -> 0.66666667 | AL2: =VLOOKUP(Table15[[#Headers],[TAN]],Table2[#All],4,FALSE)*Table112[[#This Row],[TAN]] -> 0 | AM2: =VLOOKUP(Table15[[#Headers],[TEL]],Table2[#All],4,FALSE)*Table112[[#This Row],[TEL]] -> 0.8 | AN2: =VLOOKUP(Table15[[#Headers],[TIN]],Table2[#All],4,FALSE)*Table112[[#This Row],[TIN]] -> 0.66666667 | AO2: =VLOOKUP(Table15[[#Headers],[TIT]],Table2[#All],4,FALSE)*Table112[[#This Row],[TIT]] -> 0.8 | AP2: =VLOOKUP(Table15[[#Headers],[TUN]],Table2[#All],4,FALSE)*Table112[[#This Row],[TUN]] -> 0.8 | AQ2: =VLOOKUP(Table15[[#Headers],[URA]],Table2[#All],4,FALSE)*Table112[[#This Row],[URA]] -> 0 | AR2: =VLOOKUP(Table15[[#Headers],[VAN]],Table2[#All],4,FALSE)*Table112[[#This Row],[VAN]] -> 0.6 | AS2: =VLOOKUP(Table15[[#Headers],[ZIN]],Table2[#All],4,FALSE)*Table112[[#This Row],[ZIN]] -> 0.8 | AT2: =VLOOKUP(Table15[[#Headers],[ZIR]],Table2[#All],4,FALSE)*Table112[[#This Row],[ZIR]] -> 0 | AU2: =VLOOKUP(Table15[[#Headers],[REE]],Table2[#All],4,FALSE)*Table112[[#This Row],[REE]] -> 0.30769231 | AV2: =SUM(B2:AU2) -> 18.241026
A3: AUS | B3: =VLOOKUP(Table15[[#Headers],[ALU]],Table2[#All],4,FALSE)*Table112[[#This Row],[ALU]] -> 0.66666667 | C3: =VLOOKUP(Table15[[#Headers],[ANT]],Table2[#All],4,FALSE)*Table112[[#This Row],[ANT]] -> 0 | D3: =VLOOKUP(Table15[[#Headers],[ARS]],Table2[#All],4,FALSE)*Table112[[#This Row],[ARS]] -> 0 | E3: =VLOOKUP(Table15[[#Headers],[BAR]],Table2[#All],4,FALSE)*Table112[[#This Row],[BAR]] -> 0 | F3: =VLOOKUP(Table15[[#Headers],[BER]],Table2[#All],4,FALSE)*Table112[[#This Row],[BER]] -> 0 | G3: =VLOOKUP(Table15[[#Headers],[BIS]],Table2[#All],4,FALSE)*Table112[[#This Row],[BIS]] -> 0 | H3: =VLOOKUP(Table15[[#Headers],[BOR]],Table2[#All],4,FALSE)*Table112[[#This Row],[BOR]] -> 0 | I3: =VLOOKUP(Table15[[#Headers],[CES]],Table2[#All],4,FALSE)*Table112[[#This Row],[CES]] -> 1 | J3: =VLOOKUP(Table15[[#Headers],[CHR]],Table2[#All],4,FALSE)*Table112[[#This Row],[CHR]] -> 0 | K3: =VLOOKUP(Table15[[#Headers],[COB]],Table2[#All],4,FALSE)*Table112[[#This Row],[COB]] -> 0.8 | L3: =VLOOKUP(Table15[[#Headers],[COP]],Table2[#All],4,FALSE)*Table112[[#This Row],[COP]] -> 0.57142857 | M3: =VLOOKUP(Table15[[#Headers],[FLU]],Table2[#All],4,FALSE)*Table112[[#This Row],[FLU]] -> 0 | N3: =VLOOKUP(Table15[[#Headers],[GAL]],Table2[#All],4,FALSE)*Table112[[#This Row],[GAL]] -> 0.8 | O3: =VLOOKUP(Table15[[#Headers],[GER]],Table2[#All],4,FALSE)*Table112[[#This Row],[GER]] -> 0 | P3: =VLOOKUP(Table15[[#Headers],[GRA]],Table2[#All],4,FALSE)*Table112[[#This Row],[GRA]] -> 0 | Q3: =VLOOKUP(Table15[[#Headers],[HAF]],Table2[#All],4,FALSE)*Table112[[#This Row],[HAF]] -> 0.8 | R3: =VLOOKUP(Table15[[#Headers],[IND]],Table2[#All],4,FALSE)*Table112[[#This Row],[IND]] -> 0.8 | S3: =VLOOKUP(Table15[[#Headers],[IRI]],Table2[#All],4,FALSE)*Table112[[#This Row],[IRI]] -> 0 | T3: =VLOOKUP(Table15[[#Headers],[LED]],Table2[#All],4,FALSE)*Table112[[#This Row],[LED]] -> 0.8 | U3: =VLOOKUP(Table15[[#Headers],[LIT]],Table2[#All],4,FALSE)*Table112[[#This Row],[LIT]] -> 0.66666667 | V3: =VLOOKUP(Table15[[#Headers],[MAG]],Table2[#All],4,FALSE)*Table112[[#This Row],[MAG]] -> 0 | W3: =VLOOKUP(Table15[[#Headers],[MAN]],Table2[#All],4,FALSE)*Table112[[#This Row],[MAN]] -> 0.8 | X3: =VLOOKUP(Table15[[#Headers],[MCO]],Table2[#All],4,FALSE)*Table112[[#This Row],[MCO]] -> 0.8 | Y3: =VLOOKUP(Table15[[#Headers],[NIC]],Table2[#All],4,FALSE)*Table112[[#This Row],[NIC]] -> 0.66666667 | Z3: =VLOOKUP(Table15[[#Headers],[NIO]],Table2[#All],4,FALSE)*Table112[[#This Row],[NIO]] -> 1.3333333 | AA3: =VLOOKUP(Table15[[#Headers],[PAL]],Table2[#All],4,FALSE)*Table112[[#This Row],[PAL]] -> 0 | AB3: =VLOOKUP(Table15[[#Headers],[PHO]],Table2[#All],4,FALSE)*Table112[[#This Row],[PHO]] -> 0 | AC3: =VLOOKUP(Table15[[#Headers],[PLA]],Table2[#All],4,FALSE)*Table112[[#This Row],[PLA]] -> 0 | AD3: =VLOOKUP(Table15[[#Headers],[POT]],Table2[#All],4,FALSE)*Table112[[#This Row],[POT]] -> 0 | AE3: =VLOOKUP(Table15[[#Headers],[RHE]],Table2[#All],4,FALSE)*Table112[[#This Row],[RHE]] -> 0 | AF3: =VLOOKUP(Table15[[#Headers],[RHO]],Table2[#All],4,FALSE)*Table112[[#This Row],[RHO]] -> 0 | AG3: =VLOOKUP(Table15[[#Headers],[RUB]],Table2[#All],4,FALSE)*Table112[[#This Row],[RUB]] -> 1 | AH3: =VLOOKUP(Table15[[#Headers],[RUT]],Table2[#All],4,FALSE)*Table112[[#This Row],[RUT]] -> 0 | AI3: =VLOOKUP(Table15[[#Headers],[SCA]],Table2[#All],4,FALSE)*Table112[[#This Row],[SCA]] -> 0.6 | AJ3: =VLOOKUP(Table15[[#Headers],[SIL]],Table2[#All],4,FALSE)*Table112[[#This Row],[SIL]] -> 0.8 | AK3: =VLOOKUP(Table15[[#Headers],[SLV]],Table2[#All],4,FALSE)*Table112[[#This Row],[SLV]] -> 0.66666667 | AL3: =VLOOKUP(Table15[[#Headers],[TAN]],Table2[#All],4,FALSE)*Table112[[#This Row],[TAN]] -> 0.8 | AM3: =VLOOKUP(Table15[[#Headers],[TEL]],Table2[#All],4,FALSE)*Table112[[#This Row],[TEL]] -> 0 | AN3: =VLOOKUP(Table15[[#Headers],[TIN]],Table2[#All],4,FALSE)*Table112[[#This Row],[TIN]] -> 0 | AO3: =VLOOKUP(Table15[[#Headers],[TIT]],Table2[#All],4,FALSE)*Table112[[#This Row],[TIT]] -> 0.8 | AP3: =VLOOKUP(Table15[[#Headers],[TUN]],Table2[#All],4,FALSE)*Table112[[#This Row],[TUN]] -> 0 | AQ3: =VLOOKUP(Table15[[#Headers],[URA]],Table2[#All],4,FALSE)*Table112[[#This Row],[URA]] -> 0.5 | AR3: =VLOOKUP(Table15[[#Headers],[VAN]],Table2[#All],4,FALSE)*Table112[[#This Row],[VAN]] -> 0.6 | AS3: =VLOOKUP(Table15[[#Headers],[ZIN]],Table2[#All],4,FALSE)*Table112[[#This Row],[ZIN]] -> 0.8 | AT3: =VLOOKUP(Table15[[#Headers],[ZIR]],Table2[#All],4,FALSE)*Table112[[#This Row],[ZIR]] -> 0.8 | AU3: =VLOOKUP(Table15[[#Headers],[REE]],Table2[#All],4,FALSE)*Table112[[#This Row],[REE]] -> 0.30769231 | AV3: =SUM(B3:AU3) -> 18.179121
A4: CAN | B4: =VLOOKUP(Table15[[#Headers],[ALU]],Table2[#All],4,FALSE)*Table112[[#This Row],[ALU]] -> 0 | C4: =VLOOKUP(Table15[[#Headers],[ANT]],Table2[#All],4,FALSE)*Table112[[#This Row],[ANT]] -> 0.66666667 | D4: =VLOOKUP(Table15[[#Headers],[ARS]],Table2[#All],4,FALSE) -> 0.8 | E4: =VLOOKUP(Table15[[#Headers],[BAR]],Table2[#All],4,FALSE)*Table112[[#This Row],[BAR]] -> 0 | F4: =VLOOKUP(Table15[[#Headers],[BER]],Table2[#All],4,FALSE)*Table112[[#This Row],[BER]] -> 0 | G4: =VLOOKUP(Table15[[#Headers],[BIS]],Table2[#All],4,FALSE)*Table112[[#This Row],[BIS]] -> 0 | H4: =VLOOKUP(Table15[[#Headers],[BOR]],Table2[#All],4,FALSE)*Table112[[#This Row],[BOR]] -> 0.8 | I4: =VLOOKUP(Table15[[#Headers],[CES]],Table2[#All],4,FALSE)*Table112[[#This Row],[CES]] -> 0 | J4: =VLOOKUP(Table15[[#Headers],[CHR]],Table2[#All],4,FALSE)*Table112[[#This Row],[CHR]] -> 0 | K4: =VLOOKUP(Table15[[#Headers],[COB]],Table2[#All],4,FALSE)*Table112[[#This Row],[COB]] -> 0 | L4: =VLOOKUP(Table15[[#Headers],[COP]],Table2[#All],4,FALSE)*Table112[[#This Row],[COP]] -> 0.57142857 | M4: =VLOOKUP(Table15[[#Headers],[FLU]],Table2[#All],4,FALSE)*Table112[[#This Row],[FLU]] -> 0 | N4: =VLOOKUP(Table15[[#Headers],[GAL]],Table2[#All],4,FALSE)*Table112[[#This Row],[GAL]] -> 0 | O4: =VLOOKUP(Table15[[#Headers],[GER]],Table2[#All],4,FALSE)*Table112[[#This Row],[GER]] -> 0.8 | P4: =VLOOKUP(Table15[[#Headers],[GRA]],Table2[#All],4,FALSE)*Table112[[#This Row],[GRA]] -> 0 | Q4: =VLOOKUP(Table15[[#Headers],[HAF]],Table2[#All],4,FALSE)*Table112[[#This Row],[HAF]] -> 0 | R4: =VLOOKUP(Table15[[#Headers],[IND]],Table2[#All],4,FALSE)*Table112[[#This Row],[IND]] -> 0 | S4: =VLOOKUP(Table15[[#Headers],[IRI]],Table2[#All],4,FALSE)*Table112[[#This Row],[IRI]] -> 1 | T4: =VLOOKUP(Table15[[#Headers],[LED]],Table2[#All],4,FALSE)*Table112[[#This Row],[LED]] -> 0 | U4: =VLOOKUP(Table15[[#Headers],[LIT]],Table2[#All],4,FALSE)*Table112[[#This Row],[LIT]] -> 0 | V4: =VLOOKUP(Table15[[#Headers],[MAG]],Table2[#All],4,FALSE)*Table112[[#This Row],[MAG]] -> 0.8 | W4: =VLOOKUP(Table15[[#Headers],[MAN]],Table2[#All],4,FALSE)*Table112[[#This Row],[MAN]] -> 0 | X4: =VLOOKUP(Table15[[#Headers],[MCO]],Table2[#All],4,FALSE)*Table112[[#This Row],[MCO]] -> 0.8 | Y4: =VLOOKUP(Table15[[#Headers],[NIC]],Table2[#All],4,FALSE)*Table112[[#This Row],[NIC]] -> 0.66666667 | Z4: =VLOOKUP(Table15[[#Headers],[NIO]],Table2[#All],4,FALSE)*Table112[[#This Row],[NIO]] -> 0 | AA4: =VLOOKUP(Table15[[#Headers],[PAL]],Table2[#All],4,FALSE)*Table112[[#This Row],[PAL]] -> 1 | AB4: =VLOOKUP(Table15[[#Headers],[PHO]],Table2[#All],4,FALSE)*Table112[[#This Row],[PHO]] -> 0 | AC4: =VLOOKUP(Table15[[#Headers],[PLA]],Table2[#All],4,FALSE)*Table112[[#This Row],[PLA]] -> 1 | AD4: =VLOOKUP(Table15[[#Headers],[POT]],Table2[#All],4,FALSE)*Table112[[#This Row],[POT]] -> 0.6 | AE4: =VLOOKUP(Table15[[#Headers],[RHE]],Table2[#All],4,FALSE)*Table112[[#This Row],[RHE]] -> 0 | AF4: =VLOOKUP(Table15[[#Headers],[RHO]],Table2[#All],4,FALSE)*Table112[[#This Row],[RHO]] -> 1.3333333 | AG4: =VLOOKUP(Table15[[#Headers],[RUB]],Table2[#All],4,FALSE)*Table112[[#This Row],[RUB]] -> 0 | AH4: =VLOOKUP(Table15[[#Headers],[RUT]],Table2[#All],4,FALSE)*Table112[[#This Row],[RUT]] -> 1.3333333 | AI4: =VLOOKUP(Table15[[#Headers],[SCA]],Table2[#All],4,FALSE)*Table112[[#This Row],[SCA]] -> 0.6 | AJ4: =VLOOKUP(Table15[[#Headers],[SIL]],Table2[#All],4,FALSE)*Table112[[#This Row],[SIL]] -> 0 | AK4: =VLOOKUP(Table15[[#Headers],[SLV]],Table2[#All],4,FALSE)*Table112[[#This Row],[SLV]] -> 0 | AL4: =VLOOKUP(Table15[[#Headers],[TAN]],Table2[#All],4,FALSE)*Table112[[#This Row],[TAN]] -> 0 | AM4: =VLOOKUP(Table15[[#Headers],[TEL]],Table2[#All],4,FALSE)*Table112[[#This Row],[TEL]] -> 0 | AN4: =VLOOKUP(Table15[[#Headers],[TIN]],Table2[#All],4,FALSE)*Table112[[#This Row],[TIN]] -> 0 | AO4: =VLOOKUP(Table15[[#Headers],[TIT]],Table2[#All],4,FALSE)*Table112[[#This Row],[TIT]] -> 0 | AP4: =VLOOKUP(Table15[[#Headers],[TUN]],Table2[#All],4,FALSE)*Table112[[#This Row],[TUN]] -> 0.8 | AQ4: =VLOOKUP(Table15[[#Headers],[URA]],Table2[#All],4,FALSE)*Table112[[#This Row],[URA]] -> 0 | AR4: =VLOOKUP(Table15[[#Headers],[VAN]],Table2[#All],4,FALSE)*Table112[[#This Row],[VAN]] -> 0.6 | AS4: =VLOOKUP(Table15[[#Headers],[ZIN]],Table2[#All],4,FALSE)*Table112[[#This Row],[ZIN]] -> 0 | AT4: =VLOOKUP(Table15[[#Headers],[ZIR]],Table2[#All],4,FALSE)*Table112[[#This Row],[ZIR]] -> 0 | AU4: =VLOOKUP(Table15[[#Headers],[REE]],Table2[#All],4,FALSE)*Table112[[#This Row],[REE]] -> 0.30769231 | AV4: =SUM(B4:AU4) -> 14.479121
A5: RUS | B5: =VLOOKUP(Table15[[#Headers],[ALU]],Table2[#All],4,FALSE)*Table112[[#This Row],[ALU]] -> 0 | C5: =VLOOKUP(Table15[[#Headers],[ANT]],Table2[#All],4,FALSE)*Table112[[#This Row],[ANT]] -> 0 | D5: =VLOOKUP(Table15[[#Headers],[ARS]],Table2[#All],4,FALSE) -> 0.8 | E5: =VLOOKUP(Table15[[#Headers],[BAR]],Table2[#All],4,FALSE)*Table112[[#This Row],[BAR]] -> 0 | F5: =VLOOKUP(Table15[[#Headers],[BER]],Table2[#All],4,FALSE)*Table112[[#This Row],[BER]] -> 0 | G5: =VLOOKUP(Table15[[#Headers],[BIS]],Table2[#All],4,FALSE)*Table112[[#This Row],[BIS]] -> 0 | H5: =VLOOKUP(Table15[[#Headers],[BOR]],Table2[#All],4,FALSE)*Table112[[#This Row],[BOR]] -> 0 | I5: =VLOOKUP(Table15[[#Headers],[CES]],Table2[#All],4,FALSE)*Table112[[#This Row],[CES]] -> 1 | J5: =VLOOKUP(Table15[[#Headers],[CHR]],Table2[#All],4,FALSE)*Table112[[#This Row],[CHR]] -> 0 | K5: =VLOOKUP(Table15[[#Headers],[COB]],Table2[#All],4,FALSE)*Table112[[#This Row],[COB]] -> 0.8 | L5: =VLOOKUP(Table15[[#Headers],[COP]],Table2[#All],4,FALSE)*Table112[[#This Row],[COP]] -> 0 | M5: =VLOOKUP(Table15[[#Headers],[FLU]],Table2[#All],4,FALSE)*Table112[[#This Row],[FLU]] -> 0 | N5: =VLOOKUP(Table15[[#Headers],[GAL]],Table2[#All],4,FALSE)*Table112[[#This Row],[GAL]] -> 0 | O5: =VLOOKUP(Table15[[#Headers],[GER]],Table2[#All],4,FALSE)*Table112[[#This Row],[GER]] -> 0.8 | P5: =VLOOKUP(Table15[[#Headers],[GRA]],Table2[#All],4,FALSE)*Table112[[#This Row],[GRA]] -> 0 | Q5: =VLOOKUP(Table15[[#Headers],[HAF]],Table2[#All],4,FALSE)*Table112[[#This Row],[HAF]] -> 0 | R5: =VLOOKUP(Table15[[#Headers],[IND]],Table2[#All],4,FALSE)*Table112[[#This Row],[IND]] -> 0.8 | S5: =VLOOKUP(Table15[[#Headers],[IRI]],Table2[#All],4,FALSE)*Table112[[#This Row],[IRI]] -> 1 | T5: =VLOOKUP(Table15[[#Headers],[LED]],Table2[#All],4,FALSE)*Table112[[#This Row],[LED]] -> 0 | U5: =VLOOKUP(Table15[[#Headers],[LIT]],Table2[#All],4,FALSE)*Table112[[#This Row],[LIT]] -> 0.66666667 | V5: =VLOOKUP(Table15[[#Headers],[MAG]],Table2[#All],4,FALSE)*Table112[[#This Row],[MAG]] -> 0 | W5: =VLOOKUP(Table15[[#Headers],[MAN]],Table2[#All],4,FALSE)*Table112[[#This Row],[MAN]] -> 0 | X5: =VLOOKUP(Table15[[#Headers],[MCO]],Table2[#All],4,FALSE)*Table112[[#This Row],[MCO]] -> 0.8 | Y5: =VLOOKUP(Table15[[#Headers],[NIC]],Table2[#All],4,FALSE)*Table112[[#This Row],[NIC]] -> 0.66666667 | Z5: =VLOOKUP(Table15[[#Headers],[NIO]],Table2[#All],4,FALSE)*Table112[[#This Row],[NIO]] -> 1.3333333 | AA5: =VLOOKUP(Table15[[#Headers],[PAL]],Table2[#All],4,FALSE)*Table112[[#This Row],[PAL]] -> 1 | AB5: =VLOOKUP(Table15[[#Headers],[PHO]],Table2[#All],4,FALSE)*Table112[[#This Row],[PHO]] -> 0 | AC5: =VLOOKUP(Table15[[#Headers],[PLA]],Table2[#All],4,FALSE)*Table112[[#This Row],[PLA]] -> 1 | AD5: =VLOOKUP(Table15[[#Headers],[POT]],Table2[#All],4,FALSE)*Table112[[#This Row],[POT]] -> 0.6 | AE5: =VLOOKUP(Table15[[#Headers],[RHE]],Table2[#All],4,FALSE)*Table112[[#This Row],[RHE]] -> 0 | AF5: =VLOOKUP(Table15[[#Headers],[RHO]],Table2[#All],4,FALSE)*Table112[[#This Row],[RHO]] -> 0 | AG5: =VLOOKUP(Table15[[#Headers],[RUB]],Table2[#All],4,FALSE)*Table112[[#This Row],[RUB]] -> 1 | AH5: =VLOOKUP(Table15[[#Headers],[RUT]],Table2[#All],4,FALSE)*Table112[[#This Row],[RUT]] -> 0 | AI5: =VLOOKUP(Table15[[#Headers],[SCA]],Table2[#All],4,FALSE)*Table112[[#This Row],[SCA]] -> 0 | AJ5: =VLOOKUP(Table15[[#Headers],[SIL]],Table2[#All],4,FALSE)*Table112[[#This Row],[SIL]] -> 0 | AK5: =VLOOKUP(Table15[[#Headers],[SLV]],Table2[#All],4,FALSE)*Table112[[#This Row],[SLV]] -> 0 | AL5: =VLOOKUP(Table15[[#Headers],[TAN]],Table2[#All],4,FALSE)*Table112[[#This Row],[TAN]] -> 0 | AM5: =VLOOKUP(Table15[[#Headers],[TEL]],Table2[#All],4,FALSE)*Table112[[#This Row],[TEL]] -> 0.8 | AN5: =VLOOKUP(Table15[[#Headers],[TIN]],Table2[#All],4,FALSE)*Table112[[#This Row],[TIN]] -> 0 | AO5: =VLOOKUP(Table15[[#Headers],[TIT]],Table2[#All],4,FALSE)*Table112[[#This Row],[TIT]] -> 0 | AP5: =VLOOKUP(Table15[[#Headers],[TUN]],Table2[#All],4,FALSE)*Table112[[#This Row],[TUN]] -> 0 | AQ5: =VLOOKUP(Table15[[#Headers],[URA]],Table2[#All],4,FALSE)*Table112[[#This Row],[URA]] -> 0.5 | AR5: =VLOOKUP(Table15[[#Headers],[VAN]],Table2[#All],4,FALSE)*Table112[[#This Row],[VAN]] -> 0 | AS5: =VLOOKUP(Table15[[#Headers],[ZIN]],Table2[#All],4,FALSE)*Table112[[#This Row],[ZIN]] -> 0 | AT5: =VLOOKUP(Table15[[#Headers],[ZIR]],Table2[#All],4,FALSE)*Table112[[#This Row],[ZIR]] -> 0 | AU5: =VLOOKUP(Table15[[#Headers],[REE]],Table2[#All],4,FALSE)*Table112[[#This Row],[REE]] -> 0.30769231 | AV5: =SUM(B5:AU5) -> 13.874359
A6: USA | B6: =VLOOKUP(Table15[[#Headers],[ALU]],Table2[#All],4,FALSE)*Table112[[#This Row],[ALU]] -> 0 | C6: =VLOOKUP(Table15[[#Headers],[ANT]],Table2[#All],4,FALSE)*Table112[[#This Row],[ANT]] -> 0 | D6: =VLOOKUP(Table15[[#Headers],[ARS]],Table2[#All],4,FALSE) -> 0.8 | E6: =VLOOKUP(Table15[[#Headers],[BAR]],Table2[#All],4,FALSE)*Table112[[#This Row],[BAR]] -> 0 | F6: =VLOOKUP(Table15[[#Headers],[BER]],Table2[#All],4,FALSE)*Table112[[#This Row],[BER]] -> 0 | G6: =VLOOKUP(Table15[[#Headers],[BIS]],Table2[#All],4,FALSE)*Table112[[#This Row],[BIS]] -> 0 | H6: =VLOOKUP(Table15[[#Headers],[BOR]],Table2[#All],4,FALSE)*Table112[[#This Row],[BOR]] -> 0 | I6: =VLOOKUP(Table15[[#Headers],[CES]],Table2[#All],4,FALSE)*Table112[[#This Row],[CES]] -> 0 | J6: =VLOOKUP(Table15[[#Headers],[CHR]],Table2[#All],4,FALSE)*Table112[[#This Row],[CHR]] -> 0.8 | K6: =VLOOKUP(Table15[[#Headers],[COB]],Table2[#All],4,FALSE)*Table112[[#This Row],[COB]] -> 0 | L6: =VLOOKUP(Table15[[#Headers],[COP]],Table2[#All],4,FALSE)*Table112[[#This Row],[COP]] -> 0 | M6: =VLOOKUP(Table15[[#Headers],[FLU]],Table2[#All],4,FALSE)*Table112[[#This Row],[FLU]] -> 0.8 | N6: =VLOOKUP(Table15[[#Headers],[GAL]],Table2[#All],4,FALSE)*Table112[[#This Row],[GAL]] -> 0 | O6: =VLOOKUP(Table15[[#Headers],[GER]],Table2[#All],4,FALSE)*Table112[[#This Row],[GER]] -> 0 | P6: =VLOOKUP(Table15[[#Headers],[GRA]],Table2[#All],4,FALSE)*Table112[[#This Row],[GRA]] -> 0 | Q6: =VLOOKUP(Table15[[#Headers],[HAF]],Table2[#All],4,FALSE)*Table112[[#This Row],[HAF]] -> 0.8 | R6: =VLOOKUP(Table15[[#Headers],[IND]],Table2[#All],4,FALSE)*Table112[[#This Row],[IND]] -> 0 | S6: =VLOOKUP(Table15[[#Headers],[IRI]],Table2[#All],4,FALSE)*Table112[[#This Row],[IRI]] -> 1 | T6: =VLOOKUP(Table15[[#Headers],[LED]],Table2[#All],4,FALSE)*Table112[[#This Row],[LED]] -> 0 | U6: =VLOOKUP(Table15[[#Headers],[LIT]],Table2[#All],4,FALSE)*Table112[[#This Row],[LIT]] -> 0 | V6: =VLOOKUP(Table15[[#Headers],[MAG]],Table2[#All],4,FALSE)*Table112[[#This Row],[MAG]] -> 0 | W6: =VLOOKUP(Table15[[#Headers],[MAN]],Table2[#All],4,FALSE)*Table112[[#This Row],[MAN]] -> 0.8 | X6: =VLOOKUP(Table15[[#Headers],[MCO]],Table2[#All],4,FALSE)*Table112[[#This Row],[MCO]] -> 0 | Y6: =VLOOKUP(Table15[[#Headers],[NIC]],Table2[#All],4,FALSE)*Table112[[#This Row],[NIC]] -> 0 | Z6: =VLOOKUP(Table15[[#Headers],[NIO]],Table2[#All],4,FALSE)*Table112[[#This Row],[NIO]] -> 0 | AA6: =VLOOKUP(Table15[[#Headers],[PAL]],Table2[#All],4,FALSE)*Table112[[#This Row],[PAL]] -> 1 | AB6: =VLOOKUP(Table15[[#Headers],[PHO]],Table2[#All],4,FALSE)*Table112[[#This Row],[PHO]] -> 0 | AC6: =VLOOKUP(Table15[[#Headers],[PLA]],Table2[#All],4,FALSE)*Table112[[#This Row],[PLA]] -> 1 | AD6: =VLOOKUP(Table15[[#Headers],[POT]],Table2[#All],4,FALSE)*Table112[[#This Row],[POT]] -> 0 | AE6: =VLOOKUP(Table15[[#Headers],[RHE]],Table2[#All],4,FALSE)*Table112[[#This Row],[RHE]] -> 0 | AF6: =VLOOKUP(Table15[[#Headers],[RHO]],Table2[#All],4,FALSE)*Table112[[#This Row],[RHO]] -> 1.3333333 | AG6: =VLOOKUP(Table15[[#Headers],[RUB]],Table2[#All],4,FALSE)*Table112[[#This Row],[RUB]] -> 0 | AH6: =VLOOKUP(Table15[[#Headers],[RUT]],Table2[#All],4,FALSE)*Table112[[#This Row],[RUT]] -> 1.3333333 | AI6: =VLOOKUP(Table15[[#Headers],[SCA]],Table2[#All],4,FALSE)*Table112[[#This Row],[SCA]] -> 0 | AJ6: =VLOOKUP(Table15[[#Headers],[SIL]],Table2[#All],4,FALSE)*Table112[[#This Row],[SIL]] -> 0 | AK6: =VLOOKUP(Table15[[#Headers],[SLV]],Table2[#All],4,FALSE)*Table112[[#This Row],[SLV]] -> 0 | AL6: =VLOOKUP(Table15[[#Headers],[TAN]],Table2[#All],4,FALSE)*Table112[[#This Row],[TAN]] -> 0 | AM6: =VLOOKUP(Table15[[#Headers],[TEL]],Table2[#All],4,FALSE)*Table112[[#This Row],[TEL]] -> 0 | AN6: =VLOOKUP(Table15[[#Headers],[TIN]],Table2[#All],4,FALSE)*Table112[[#This Row],[TIN]] -> 0 | AO6: =VLOOKUP(Table15[[#Headers],[TIT]],Table2[#All],4,FALSE)*Table112[[#This Row],[TIT]] -> 0.8 | AP6: =VLOOKUP(Table15[[#Headers],[TUN]],Table2[#All],4,FALSE)*Table112[[#This Row],[TUN]] -> 0 | AQ6: =VLOOKUP(Table15[[#Headers],[URA]],Table2[#All],4,FALSE)*Table112[[#This Row],[URA]] -> 0 | AR6: =VLOOKUP(Table15[[#Headers],[VAN]],Table2[#All],4,FALSE)*Table112[[#This Row],[VAN]] -> 0.6 | AS6: =VLOOKUP(Table15[[#Headers],[ZIN]],Table2[#All],4,FALSE)*Table112[[#This Row],[ZIN]] -> 0 | AT6: =VLOOKUP(Table15[[#Headers],[ZIR]],Table2[#All],4,FALSE)*Table112[[#This Row],[ZIR]] -> 0.8 | AU6: =VLOOKUP(Table15[[#Headers],[REE]],Table2[#All],4,FALSE)*Table112[[#This Row],[REE]] -> 0.30769231 | AV6: =SUM(B6:AU6) -> 12.174359
A7: ZAF | B7: =VLOOKUP(Table15[[#Headers],[ALU]],Table2[#All],4,FALSE)*Table112[[#This Row],[ALU]] -> 0 | C7: =VLOOKUP(Table15[[#Headers],[ANT]],Table2[#All],4,FALSE)*Table112[[#This Row],[ANT]] -> 0 | D7: =VLOOKUP(Table15[[#Headers],[ARS]],Table2[#All],4,FALSE) -> 0.8 | E7: =VLOOKUP(Table15[[#Headers],[BAR]],Table2[#All],4,FALSE)*Table112[[#This Row],[BAR]] -> 0.8 | F7: =VLOOKUP(Table15[[#Headers],[BER]],Table2[#All],4,FALSE)*Table112[[#This Row],[BER]] -> 0.8 | G7: =VLOOKUP(Table15[[#Headers],[BIS]],Table2[#All],4,FALSE)*Table112[[#This Row],[BIS]] -> 0 | H7: =VLOOKUP(Table15[[#Headers],[BOR]],Table2[#All],4,FALSE)*Table112[[#This Row],[BOR]] -> 0.8 | I7: =VLOOKUP(Table15[[#Headers],[CES]],Table2[#All],4,FALSE)*Table112[[#This Row],[CES]] -> 0 | J7: =VLOOKUP(Table15[[#Headers],[CHR]],Table2[#All],4,FALSE)*Table112[[#This Row],[CHR]] -> 0 | K7: =VLOOKUP(Table15[[#Headers],[COB]],Table2[#All],4,FALSE)*Table112[[#This Row],[COB]] -> 0 | L7: =VLOOKUP(Table15[[#Headers],[COP]],Table2[#All],4,FALSE)*Table112[[#This Row],[COP]] -> 0.57142857 | M7: =VLOOKUP(Table15[[#Headers],[FLU]],Table2[#All],4,FALSE)*Table112[[#This Row],[FLU]] -> 0 | N7: =VLOOKUP(Table15[[#Headers],[GAL]],Table2[#All],4,FALSE)*Table112[[#This Row],[GAL]] -> 0 | O7: =VLOOKUP(Table15[[#Headers],[GER]],Table2[#All],4,FALSE)*Table112[[#This Row],[GER]] -> 0.8 | P7: =VLOOKUP(Table15[[#Headers],[GRA]],Table2[#All],4,FALSE)*Table112[[#This Row],[GRA]] -> 0 | Q7: =VLOOKUP(Table15[[#Headers],[HAF]],Table2[#All],4,FALSE)*Table112[[#This Row],[HAF]] -> 0.8 | R7: =VLOOKUP(Table15[[#Headers],[IND]],Table2[#All],4,FALSE)*Table112[[#This Row],[IND]] -> 0 | S7: =VLOOKUP(Table15[[#Headers],[IRI]],Table2[#All],4,FALSE)*Table112[[#This Row],[IRI]] -> 0 | T7: =VLOOKUP(Table15[[#Headers],[LED]],Table2[#All],4,FALSE)*Table112[[#This Row],[LED]] -> 0.8 | U7: =VLOOKUP(Table15[[#Headers],[LIT]],Table2[#All],4,FALSE)*Table112[[#This Row],[LIT]] -> 0 | V7: =VLOOKUP(Table15[[#Headers],[MAG]],Table2[#All],4,FALSE)*Table112[[#This Row],[MAG]] -> 0 | W7: =VLOOKUP(Table15[[#Headers],[MAN]],Table2[#All],4,FALSE)*Table112[[#This Row],[MAN]] -> 0 | X7: =VLOOKUP(Table15[[#Headers],[MCO]],Table2[#All],4,FALSE)*Table112[[#This Row],[MCO]] -> 0.8 | Y7: =VLOOKUP(Table15[[#Headers],[NIC]],Table2[#All],4,FALSE)*Table112[[#This Row],[NIC]] -> 0 | Z7: =VLOOKUP(Table15[[#Headers],[NIO]],Table2[#All],4,FALSE)*Table112[[#This Row],[NIO]] -> 0 | AA7: =VLOOKUP(Table15[[#Headers],[PAL]],Table2[#All],4,FALSE)*Table112[[#This Row],[PAL]] -> 1 | AB7: =VLOOKUP(Table15[[#Headers],[PHO]],Table2[#All],4,FALSE)*Table112[[#This Row],[PHO]] -> 0 | AC7: =VLOOKUP(Table15[[#Headers],[PLA]],Table2[#All],4,FALSE)*Table112[[#This Row],[PLA]] -> 0 | AD7: =VLOOKUP(Table15[[#Headers],[POT]],Table2[#All],4,FALSE)*Table112[[#This Row],[POT]] -> 0 | AE7: =VLOOKUP(Table15[[#Headers],[RHE]],Table2[#All],4,FALSE)*Table112[[#This Row],[RHE]] -> 0.8 | AF7: =VLOOKUP(Table15[[#Headers],[RHO]],Table2[#All],4,FALSE)*Table112[[#This Row],[RHO]] -> 0 | AG7: =VLOOKUP(Table15[[#Headers],[RUB]],Table2[#All],4,FALSE)*Table112[[#This Row],[RUB]] -> 0 | AH7: =VLOOKUP(Table15[[#Headers],[RUT]],Table2[#All],4,FALSE)*Table112[[#This Row],[RUT]] -> 0 | AI7: =VLOOKUP(Table15[[#Headers],[SCA]],Table2[#All],4,FALSE)*Table112[[#This Row],[SCA]] -> 0 | AJ7: =VLOOKUP(Table15[[#Headers],[SIL]],Table2[#All],4,FALSE)*Table112[[#This Row],[SIL]] -> 0.8 | AK7: =VLOOKUP(Table15[[#Headers],[SLV]],Table2[#All],4,FALSE)*Table112[[#This Row],[SLV]] -> 0 | AL7: =VLOOKUP(Table15[[#Headers],[TAN]],Table2[#All],4,FALSE)*Table112[[#This Row],[TAN]] -> 0 | AM7: =VLOOKUP(Table15[[#Headers],[TEL]],Table2[#All],4,FALSE)*Table112[[#This Row],[TEL]] -> 0 | AN7: =VLOOKUP(Table15[[#Headers],[TIN]],Table2[#All],4,FALSE)*Table112[[#This Row],[TIN]] -> 0 | AO7: =VLOOKUP(Table15[[#Headers],[TIT]],Table2[#All],4,FALSE)*Table112[[#This Row],[TIT]] -> 0 | AP7: =VLOOKUP(Table15[[#Headers],[TUN]],Table2[#All],4,FALSE)*Table112[[#This Row],[TUN]] -> 0 | AQ7: =VLOOKUP(Table15[[#Headers],[URA]],Table2[#All],4,FALSE)*Table112[[#This Row],[URA]] -> 0 | AR7: =VLOOKUP(Table15[[#Headers],[VAN]],Table2[#All],4,FALSE)*Table112[[#This Row],[VAN]] -> 0 | AS7: =VLOOKUP(Table15[[#Headers],[ZIN]],Table2[#All],4,FALSE)*Table112[[#This Row],[ZIN]] -> 0 | AT7: =VLOOKUP(Table15[[#Headers],[ZIR]],Table2[#All],4,FALSE)*Table112[[#This Row],[ZIR]] -> 0.8 | AU7: =VLOOKUP(Table15[[#Headers],[REE]],Table2[#All],4,FALSE)*Table112[[#This Row],[REE]] -> 0.30769231 | AV7: =SUM(B7:AU7) -> 10.679121
A8: BRA | B8: =VLOOKUP(Table15[[#Headers],[ALU]],Table2[#All],4,FALSE)*Table112[[#This Row],[ALU]] -> 0.66666667 | C8: =VLOOKUP(Table15[[#Headers],[ANT]],Table2[#All],4,FALSE)*Table112[[#This Row],[ANT]] -> 0 | D8: =VLOOKUP(Table15[[#Headers],[ARS]],Table2[#All],4,FALSE) -> 0.8 | E8: =VLOOKUP(Table15[[#Headers],[BAR]],Table2[#All],4,FALSE)*Table112[[#This Row],[BAR]] -> 0 | F8: =VLOOKUP(Table15[[#Headers],[BER]],Table2[#All],4,FALSE)*Table112[[#This Row],[BER]] -> 0.8 | G8: =VLOOKUP(Table15[[#Headers],[BIS]],Table2[#All],4,FALSE)*Table112[[#This Row],[BIS]] -> 0 | H8: =VLOOKUP(Table15[[#Headers],[BOR]],Table2[#All],4,FALSE)*Table112[[#This Row],[BOR]] -> 0 | I8: =VLOOKUP(Table15[[#Headers],[CES]],Table2[#All],4,FALSE)*Table112[[#This Row],[CES]] -> 0 | J8: =VLOOKUP(Table15[[#Headers],[CHR]],Table2[#All],4,FALSE)*Table112[[#This Row],[CHR]] -> 0 | K8: =VLOOKUP(Table15[[#Headers],[COB]],Table2[#All],4,FALSE)*Table112[[#This Row],[COB]] -> 0 | L8: =VLOOKUP(Table15[[#Headers],[COP]],Table2[#All],4,FALSE)*Table112[[#This Row],[COP]] -> 0 | M8: =VLOOKUP(Table15[[#Headers],[FLU]],Table2[#All],4,FALSE)*Table112[[#This Row],[FLU]] -> 0 | N8: =VLOOKUP(Table15[[#Headers],[GAL]],Table2[#All],4,FALSE)*Table112[[#This Row],[GAL]] -> 0 | O8: =VLOOKUP(Table15[[#Headers],[GER]],Table2[#All],4,FALSE)*Table112[[#This Row],[GER]] -> 0 | P8: =VLOOKUP(Table15[[#Headers],[GRA]],Table2[#All],4,FALSE)*Table112[[#This Row],[GRA]] -> 0.66666667 | Q8: =VLOOKUP(Table15[[#Headers],[HAF]],Table2[#All],4,FALSE)*Table112[[#This Row],[HAF]] -> 0 | R8: =VLOOKUP(Table15[[#Headers],[IND]],Table2[#All],4,FALSE)*Table112[[#This Row],[IND]] -> 0 | S8: =VLOOKUP(Table15[[#Headers],[IRI]],Table2[#All],4,FALSE)*Table112[[#This Row],[IRI]] -> 0 | T8: =VLOOKUP(Table15[[#Headers],[LED]],Table2[#All],4,FALSE)*Table112[[#This Row],[LED]] -> 0 | U8: =VLOOKUP(Table15[[#Headers],[LIT]],Table2[#All],4,FALSE)*Table112[[#This Row],[LIT]] -> 0 | V8: =VLOOKUP(Table15[[#Headers],[MAG]],Table2[#All],4,FALSE)*Table112[[#This Row],[MAG]] -> 0.8 | W8: =VLOOKUP(Table15[[#Headers],[MAN]],Table2[#All],4,FALSE)*Table112[[#This Row],[MAN]] -> 0.8 | X8: =VLOOKUP(Table15[[#Headers],[MCO]],Table2[#All],4,FALSE)*Table112[[#This Row],[MCO]] -> 0 | Y8: =VLOOKUP(Table15[[#Headers],[NIC]],Table2[#All],4,FALSE)*Table112[[#This Row],[NIC]] -> 0.66666667 | Z8: =VLOOKUP(Table15[[#Headers],[NIO]],Table2[#All],4,FALSE)*Table112[[#This Row],[NIO]] -> 1.3333333 | AA8: =VLOOKUP(Table15[[#Headers],[PAL]],Table2[#All],4,FALSE)*Table112[[#This Row],[PAL]] -> 0 | AB8: =VLOOKUP(Table15[[#Headers],[PHO]],Table2[#All],4,FALSE)*Table112[[#This Row],[PHO]] -> 0 | AC8: =VLOOKUP(Table15[[#Headers],[PLA]],Table2[#All],4,FALSE)*Table112[[#This Row],[PLA]] -> 0 | AD8: =VLOOKUP(Table15[[#Headers],[POT]],Table2[#All],4,FALSE)*Table112[[#This Row],[POT]] -> 0 | AE8: =VLOOKUP(Table15[[#Headers],[RHE]],Table2[#All],4,FALSE)*Table112[[#This Row],[RHE]] -> 0 | AF8: =VLOOKUP(Table15[[#Headers],[RHO]],Table2[#All],4,FALSE)*Table112[[#This Row],[RHO]] -> 0 | AG8: =VLOOKUP(Table15[[#Headers],[RUB]],Table2[#All],4,FALSE)*Table112[[#This Row],[RUB]] -> 0 | AH8: =VLOOKUP(Table15[[#Headers],[RUT]],Table2[#All],4,FALSE)*Table112[[#This Row],[RUT]] -> 0 | AI8: =VLOOKUP(Table15[[#Headers],[SCA]],Table2[#All],4,FALSE)*Table112[[#This Row],[SCA]] -> 0 | AJ8: =VLOOKUP(Table15[[#Headers],[SIL]],Table2[#All],4,FALSE)*Table112[[#This Row],[SIL]] -> 0.8 | AK8: =VLOOKUP(Table15[[#Headers],[SLV]],Table2[#All],4,FALSE)*Table112[[#This Row],[SLV]] -> 0 | AL8: =VLOOKUP(Table15[[#Headers],[TAN]],Table2[#All],4,FALSE)*Table112[[#This Row],[TAN]] -> 0.8 | AM8: =VLOOKUP(Table15[[#Headers],[TEL]],Table2[#All],4,FALSE)*Table112[[#This Row],[TEL]] -> 0 | AN8: =VLOOKUP(Table15[[#Headers],[TIN]],Table2[#All],4,FALSE)*Table112[[#This Row],[TIN]] -> 0 | AO8: =VLOOKUP(Table15[[#Headers],[TIT]],Table2[#All],4,FALSE)*Table112[[#This Row],[TIT]] -> 0 | AP8: =VLOOKUP(Table15[[#Headers],[TUN]],Table2[#All],4,FALSE)*Table112[[#This Row],[TUN]] -> 0 | AQ8: =VLOOKUP(Table15[[#Headers],[URA]],Table2[#All],4,FALSE)*Table112[[#This Row],[URA]] -> 0 | AR8: =VLOOKUP(Table15[[#Headers],[VAN]],Table2[#All],4,FALSE)*Table112[[#This Row],[VAN]] -> 0.6 | AS8: =VLOOKUP(Table15[[#Headers],[ZIN]],Table2[#All],4,FALSE)*Table112[[#This Row],[ZIN]] -> 0 | AT8: =VLOOKUP(Table15[[#Headers],[ZIR]],Table2[#All],4,FALSE)*Table112[[#This Row],[ZIR]] -> 0 | AU8: =VLOOKUP(Table15[[#Headers],[REE]],Table2[#All],4,FALSE)*Table112[[#This Row],[REE]] -> 0.30769231 | AV8: =SUM(B8:AU8) -> 9.0410256
A9: PER | B9: =VLOOKUP(Table15[[#Headers],[ALU]],Table2[#All],4,FALSE)*Table112[[#This Row],[ALU]] -> 0 | C9: =VLOOKUP(Table15[[#Headers],[ANT]],Table2[#All],4,FALSE)*Table112[[#This Row],[ANT]] -> 0 | D9: =VLOOKUP(Table15[[#Headers],[ARS]],Table2[#All],4,FALSE) -> 0.8 | E9: =VLOOKUP(Table15[[#Headers],[BAR]],Table2[#All],4,FALSE)*Table112[[#This Row],[BAR]] -> 0 | F9: =VLOOKUP(Table15[[#Headers],[BER]],Table2[#All],4,FALSE)*Table112[[#This Row],[BER]] -> 0 | G9: =VLOOKUP(Table15[[#Headers],[BIS]],Table2[#All],4,FALSE)*Table112[[#This Row],[BIS]] -> 0.8 | H9: =VLOOKUP(Table15[[#Headers],[BOR]],Table2[#All],4,FALSE)*Table112[[#This Row],[BOR]] -> 0 | I9: =VLOOKUP(Table15[[#Headers],[CES]],Table2[#All],4,FALSE)*Table112[[#This Row],[CES]] -> 0 | J9: =VLOOKUP(Table15[[#Headers],[CHR]],Table2[#All],4,FALSE)*Table112[[#This Row],[CHR]] -> 0 | K9: =VLOOKUP(Table15[[#Headers],[COB]],Table2[#All],4,FALSE)*Table112[[#This Row],[COB]] -> 0 | L9: =VLOOKUP(Table15[[#Headers],[COP]],Table2[#All],4,FALSE)*Table112[[#This Row],[COP]] -> 0.57142857 | M9: =VLOOKUP(Table15[[#Headers],[FLU]],Table2[#All],4,FALSE)*Table112[[#This Row],[FLU]] -> 0 | N9: =VLOOKUP(Table15[[#Headers],[GAL]],Table2[#All],4,FALSE)*Table112[[#This Row],[GAL]] -> 0 | O9: =VLOOKUP(Table15[[#Headers],[GER]],Table2[#All],4,FALSE)*Table112[[#This Row],[GER]] -> 0 | P9: =VLOOKUP(Table15[[#Headers],[GRA]],Table2[#All],4,FALSE)*Table112[[#This Row],[GRA]] -> 0 | Q9: =VLOOKUP(Table15[[#Headers],[HAF]],Table2[#All],4,FALSE)*Table112[[#This Row],[HAF]] -> 0 | R9: =VLOOKUP(Table15[[#Headers],[IND]],Table2[#All],4,FALSE)*Table112[[#This Row],[IND]] -> 0.8 | S9: =VLOOKUP(Table15[[#Headers],[IRI]],Table2[#All],4,FALSE)*Table112[[#This Row],[IRI]] -> 0 | T9: =VLOOKUP(Table15[[#Headers],[LED]],Table2[#All],4,FALSE)*Table112[[#This Row],[LED]] -> 0.8 | U9: =VLOOKUP(Table15[[#Headers],[LIT]],Table2[#All],4,FALSE)*Table112[[#This Row],[LIT]] -> 0 | V9: =VLOOKUP(Table15[[#Headers],[MAG]],Table2[#All],4,FALSE)*Table112[[#This Row],[MAG]] -> 0 | W9: =VLOOKUP(Table15[[#Headers],[MAN]],Table2[#All],4,FALSE)*Table112[[#This Row],[MAN]] -> 0 | X9: =VLOOKUP(Table15[[#Headers],[MCO]],Table2[#All],4,FALSE)*Table112[[#This Row],[MCO]] -> 0 | Y9: =VLOOKUP(Table15[[#Headers],[NIC]],Table2[#All],4,FALSE)*Table112[[#This Row],[NIC]] -> 0 | Z9: =VLOOKUP(Table15[[#Headers],[NIO]],Table2[#All],4,FALSE)*Table112[[#This Row],[NIO]] -> 0 | AA9: =VLOOKUP(Table15[[#Headers],[PAL]],Table2[#All],4,FALSE)*Table112[[#This Row],[PAL]] -> 0 | AB9: =VLOOKUP(Table15[[#Headers],[PHO]],Table2[#All],4,FALSE)*Table112[[#This Row],[PHO]] -> 0 | AC9: =VLOOKUP(Table15[[#Headers],[PLA]],Table2[#All],4,FALSE)*Table112[[#This Row],[PLA]] -> 0 | AD9: =VLOOKUP(Table15[[#Headers],[POT]],Table2[#All],4,FALSE)*Table112[[#This Row],[POT]] -> 0 | AE9: =VLOOKUP(Table15[[#Headers],[RHE]],Table2[#All],4,FALSE)*Table112[[#This Row],[RHE]] -> 0.8 | AF9: =VLOOKUP(Table15[[#Headers],[RHO]],Table2[#All],4,FALSE)*Table112[[#This Row],[RHO]] -> 0 | AG9: =VLOOKUP(Table15[[#Headers],[RUB]],Table2[#All],4,FALSE)*Table112[[#This Row],[RUB]] -> 0 | AH9: =VLOOKUP(Table15[[#Headers],[RUT]],Table2[#All],4,FALSE)*Table112[[#This Row],[RUT]] -> 0 | AI9: =VLOOKUP(Table15[[#Headers],[SCA]],Table2[#All],4,FALSE)*Table112[[#This Row],[SCA]] -> 0 | AJ9: =VLOOKUP(Table15[[#Headers],[SIL]],Table2[#All],4,FALSE)*Table112[[#This Row],[SIL]] -> 0 | AK9: =VLOOKUP(Table15[[#Headers],[SLV]],Table2[#All],4,FALSE)*Table112[[#This Row],[SLV]] -> 0.66666667 | AL9: =VLOOKUP(Table15[[#Headers],[TAN]],Table2[#All],4,FALSE)*Table112[[#This Row],[TAN]] -> 0 | AM9: =VLOOKUP(Table15[[#Headers],[TEL]],Table2[#All],4,FALSE)*Table112[[#This Row],[TEL]] -> 0.8 | AN9: =VLOOKUP(Table15[[#Headers],[TIN]],Table2[#All],4,FALSE)*Table112[[#This Row],[TIN]] -> 0.66666667 | AO9: =VLOOKUP(Table15[[#Headers],[TIT]],Table2[#All],4,FALSE)*Table112[[#This Row],[TIT]] -> 0 | AP9: =VLOOKUP(Table15[[#Headers],[TUN]],Table2[#All],4,FALSE)*Table112[[#This Row],[TUN]] -> 0 | AQ9: =VLOOKUP(Table15[[#Headers],[URA]],Table2[#All],4,FALSE)*Table112[[#This Row],[URA]] -> 0 | AR9: =VLOOKUP(Table15[[#Headers],[VAN]],Table2[#All],4,FALSE)*Table112[[#This Row],[VAN]] -> 0 | AS9: =VLOOKUP(Table15[[#Headers],[ZIN]],Table2[#All],4,FALSE)*Table112[[#This Row],[ZIN]] -> 0.8 | AT9: =VLOOKUP(Table15[[#Headers],[ZIR]],Table2[#All],4,FALSE)*Table112[[#This Row],[ZIR]] -> 0 | AU9: =VLOOKUP(Table15[[#Headers],[REE]],Table2[#All],4,FALSE)*Table112[[#This Row],[REE]] -> 0 | AV9: =SUM(B9:AU9) -> 7.5047619
A10: CHL | B10: =VLOOKUP(Table15[[#Headers],[ALU]],Table2[#All],4,FALSE)*Table112[[#This Row],[ALU]] -> 0.66666667 | C10: =VLOOKUP(Table15[[#Headers],[ANT]],Table2[#All],4,FALSE)*Table112[[#This Row],[ANT]] -> 0 | D10: =VLOOKUP(Table15[[#Headers],[ARS]],Table2[#All],4,FALSE) -> 0.8 | E10: =VLOOKUP(Table15[[#Headers],[BAR]],Table2[#All],4,FALSE)*Table112[[#This Row],[BAR]] -> 0.8 | F10: =VLOOKUP(Table15[[#Headers],[BER]],Table2[#All],4,FALSE)*Table112[[#This Row],[BER]] -> 0 | G10: =VLOOKUP(Table15[[#Headers],[BIS]],Table2[#All],4,FALSE)*Table112[[#This Row],[BIS]] -> 0 | H10: =VLOOKUP(Table15[[#Headers],[BOR]],Table2[#All],4,FALSE)*Table112[[#This Row],[BOR]] -> 0 | I10: =VLOOKUP(Table15[[#Headers],[CES]],Table2[#All],4,FALSE)*Table112[[#This Row],[CES]] -> 0 | J10: =VLOOKUP(Table15[[#Headers],[CHR]],Table2[#All],4,FALSE)*Table112[[#This Row],[CHR]] -> 0.8 | K10: =VLOOKUP(Table15[[#Headers],[COB]],Table2[#All],4,FALSE)*Table112[[#This Row],[COB]] -> 0 | L10: =VLOOKUP(Table15[[#Headers],[COP]],Table2[#All],4,FALSE)*Table112[[#This Row],[COP]] -> 0 | M10: =VLOOKUP(Table15[[#Headers],[FLU]],Table2[#All],4,FALSE)*Table112[[#This Row],[FLU]] -> 0 | N10: =VLOOKUP(Table15[[#Headers],[GAL]],Table2[#All],4,FALSE)*Table112[[#This Row],[GAL]] -> 0 | O10: =VLOOKUP(Table15[[#Headers],[GER]],Table2[#All],4,FALSE)*Table112[[#This Row],[GER]] -> 0 | P10: =VLOOKUP(Table15[[#Headers],[GRA]],Table2[#All],4,FALSE)*Table112[[#This Row],[GRA]] -> 0.66666667 | Q10: =VLOOKUP(Table15[[#Headers],[HAF]],Table2[#All],4,FALSE)*Table112[[#This Row],[HAF]] -> 0.8 | R10: =VLOOKUP(Table15[[#Headers],[IND]],Table2[#All],4,FALSE)*Table112[[#This Row],[IND]] -> 0 | S10: =VLOOKUP(Table15[[#Headers],[IRI]],Table2[#All],4,FALSE)*Table112[[#This Row],[IRI]] -> 0 | T10: =VLOOKUP(Table15[[#Headers],[LED]],Table2[#All],4,FALSE)*Table112[[#This Row],[LED]] -> 0 | U10: =VLOOKUP(Table15[[#Headers],[LIT]],Table2[#All],4,FALSE)*Table112[[#This Row],[LIT]] -> 0 | V10: =VLOOKUP(Table15[[#Headers],[MAG]],Table2[#All],4,FALSE)*Table112[[#This Row],[MAG]] -> 0 | W10: =VLOOKUP(Table15[[#Headers],[MAN]],Table2[#All],4,FALSE)*Table112[[#This Row],[MAN]] -> 0 | X10: =VLOOKUP(Table15[[#Headers],[MCO]],Table2[#All],4,FALSE)*Table112[[#This Row],[MCO]] -> 0 | Y10: =VLOOKUP(Table15[[#Headers],[NIC]],Table2[#All],4,FALSE)*Table112[[#This Row],[NIC]] -> 0 | Z10: =VLOOKUP(Table15[[#Headers],[NIO]],Table2[#All],4,FALSE)*Table112[[#This Row],[NIO]] -> 0 | AA10: =VLOOKUP(Table15[[#Headers],[PAL]],Table2[#All],4,FALSE)*Table112[[#This Row],[PAL]] -> 0 | AB10: =VLOOKUP(Table15[[#Headers],[PHO]],Table2[#All],4,FALSE)*Table112[[#This Row],[PHO]] -> 0 | AC10: =VLOOKUP(Table15[[#Headers],[PLA]],Table2[#All],4,FALSE)*Table112[[#This Row],[PLA]] -> 0 | AD10: =VLOOKUP(Table15[[#Headers],[POT]],Table2[#All],4,FALSE)*Table112[[#This Row],[POT]] -> 0 | AE10: =VLOOKUP(Table15[[#Headers],[RHE]],Table2[#All],4,FALSE)*Table112[[#This Row],[RHE]] -> 0 | AF10: =VLOOKUP(Table15[[#Headers],[RHO]],Table2[#All],4,FALSE)*Table112[[#This Row],[RHO]] -> 0 | AG10: =VLOOKUP(Table15[[#Headers],[RUB]],Table2[#All],4,FALSE)*Table112[[#This Row],[RUB]] -> 0 | AH10: =VLOOKUP(Table15[[#Headers],[RUT]],Table2[#All],4,FALSE)*Table112[[#This Row],[RUT]] -> 0 | AI10: =VLOOKUP(Table15[[#Headers],[SCA]],Table2[#All],4,FALSE)*Table112[[#This Row],[SCA]] -> 0 | AJ10: =VLOOKUP(Table15[[#Headers],[SIL]],Table2[#All],4,FALSE)*Table112[[#This Row],[SIL]] -> 0 | AK10: =VLOOKUP(Table15[[#Headers],[SLV]],Table2[#All],4,FALSE)*Table112[[#This Row],[SLV]] -> 0 | AL10: =VLOOKUP(Table15[[#Headers],[TAN]],Table2[#All],4,FALSE)*Table112[[#This Row],[TAN]] -> 0 | AM10: =VLOOKUP(Table15[[#Headers],[TEL]],Table2[#All],4,FALSE)*Table112[[#This Row],[TEL]] -> 0 | AN10: =VLOOKUP(Table15[[#Headers],[TIN]],Table2[#All],4,FALSE)*Table112[[#This Row],[TIN]] -> 0 | AO10: =VLOOKUP(Table15[[#Headers],[TIT]],Table2[#All],4,FALSE)*Table112[[#This Row],[TIT]] -> 0.8 | AP10: =VLOOKUP(Table15[[#Headers],[TUN]],Table2[#All],4,FALSE)*Table112[[#This Row],[TUN]] -> 0 | AQ10: =VLOOKUP(Table15[[#Headers],[URA]],Table2[#All],4,FALSE)*Table112[[#This Row],[URA]] -> 0 | AR10: =VLOOKUP(Table15[[#Headers],[VAN]],Table2[#All],4,FALSE)*Table112[[#This Row],[VAN]] -> 0 | AS10: =VLOOKUP(Table15[[#Headers],[ZIN]],Table2[#All],4,FALSE)*Table112[[#This Row],[ZIN]] -> 0.8 | AT10: =VLOOKUP(Table15[[#Headers],[ZIR]],Table2[#All],4,FALSE)*Table112[[#This Row],[ZIR]] -> 0.8 | AU10: =VLOOKUP(Table15[[#Headers],[REE]],Table2[#All],4,FALSE)*Table112[[#This Row],[REE]] -> 0.30769231 | AV10: =SUM(B10:AU10) -> 7.2410256
